Workbook

Sheet Assumptions
B2: Netflix | E2: SCENARIO SELECTION -> | G2: =+Valuation!M2 -> 1 | H2: Función | I2: Offset
B3: Model Assumptions | G3: =IF(G2=1,"Base Case", IF(G2=2,"Bull Case", IF(G2=3,"Bear Case","-"))) -> Base Case | I3: Desref
B5: Assumptions Netflix | D5: FY2021 | E5: FY2022 | F5: FY2023 | G5: FY2024 | H5: FY2025 | I5: FY2026 | J5: FY2027
B7: Revenues United Estates & Canada | D7: =OFFSET(D7,$G$2,,,) -> 12972100 | E7: {=OFFSET(E7,$G$2,,,)} -> 13893119 | F7: {=OFFSET(F7,$G$2,,,)} -> 14879531 | G7: =OFFSET(G7,$G$2,,,) -> 15935977 | H7: =OFFSET(H7,$G$2,,,) -> 17067432 | I7: =OFFSET(I7,$G$2,,,) -> 18279219 | J7: =OFFSET(J7,$G$2,,,) -> 19577044
B8: Base Case | D8: 12972100 | E8: =+E13*E23 -> 13893119 | F8: =+F13*F23 -> 14879531 | G8: =+G13*G23 -> 15935977 | H8: =+H13*H23 -> 17067432 | I8: =+I13*I23 -> 18279219 | J8: =+J13*J23 -> 19577044
B9: Bull Case | D9: 12972100 | E9: =+E14*E24 -> 14162939 | F9: =+F14*F24 -> 15463097 | G9: =+G14*G24 -> 16882609 | H9: =+H14*H24 -> 18432432 | I9: =+I14*I24 -> 20124530 | J9: =+J14*J24 -> 21971961
B10: Bear Case | D10: 12972100 | E10: =+E15*E25 -> 13363857 | F10: =+F15*F25 -> 13767446 | G10: =+G15*G25 -> 14183223 | H10: =+H15*H25 -> 14611556 | I10: =+I15*I25 -> 15052825 | J10: =+J15*J25 -> 15507420
B12: Paid Mememberships United Estates & Canada | D12: =OFFSET(D12,$G$2,,,) -> 75215 | E12: =OFFSET(E12,$G$2,,,) -> 76719.3 | F12: =OFFSET(F12,$G$2,,,) -> 78253.686 | G12: =OFFSET(G12,$G$2,,,) -> 79818.76 | H12: =OFFSET(H12,$G$2,,,) -> 81415.135 | I12: =OFFSET(I12,$G$2,,,) -> 83043.438 | J12: =OFFSET(J12,$G$2,,,) -> 84704.306
B13: Base Case | D13: 75215 | E13: =+D13*(1+E18) -> 76719.3 | F13: =+E13*(1+F18) -> 78253.686 | G13: =+F13*(1+G18) -> 79818.76 | H13: =+G13*(1+H18) -> 81415.135 | I13: =+H13*(1+I18) -> 83043.438 | J13: =+I13*(1+J18) -> 84704.306
B14: Bull Case | D14: 75215 | E14: =+D14*(1+E19) -> 77471.45 | F14: =+E14*(1+F19) -> 79795.594 | G14: =+F14*(1+G19) -> 82189.461 | H14: =+G14*(1+H19) -> 84655.145 | I14: =+H14*(1+I19) -> 87194.799 | J14: =+I14*(1+J19) -> 89810.643
B15: Bear Case | D15: 75215 | E15: =+D15*(1+E20) -> 75967.15 | F15: =+E15*(1+F20) -> 76726.822 | G15: =+F15*(1+G20) -> 77494.09 | H15: =+G15*(1+H20) -> 78269.031 | I15: =+H15*(1+I20) -> 79051.721 | J15: =+I15*(1+J20) -> 79842.238
B17: Paid Mememberships Growth United Estates & Canada | D17: =OFFSET(D17,$G$2,,,) | E17: =OFFSET(E17,$G$2,,,) -> 0.02 | F17: =OFFSET(F17,$G$2,,,) -> 0.02 | G17: =OFFSET(G17,$G$2,,,) -> 0.02 | H17: =OFFSET(H17,$G$2,,,) -> 0.02 | I17: =OFFSET(I17,$G$2,,,) -> 0.02 | J17: =OFFSET(J17,$G$2,,,) -> 0.02
B18: Base Case | E18: 0.02 | F18: 0.02 | G18: 0.02 | H18: 0.02 | I18: 0.02 | J18: 0.02
B19: Bull Case | E19: 0.03 | F19: 0.03 | G19: 0.03 | H19: 0.03 | I19: 0.03 | J19: 0.03
B20: Bear Case | E20: 0.01 | F20: 0.01 | G20: 0.01 | H20: 0.01 | I20: 0.01 | J20: 0.01
B22: Average Price United Estates & Canada | D22: =OFFSET(D22,$G$2,,,) -> 172.46693 | E22: =OFFSET(E22,$G$2,,,) -> 181.09027 | F22: =OFFSET(F22,$G$2,,,) -> 190.14479 | G22: =OFFSET(G22,$G$2,,,) -> 199.65203 | H22: =OFFSET(H22,$G$2,,,) -> 209.63463 | I22: =OFFSET(I22,$G$2,,,) -> 220.11636 | J22: =OFFSET(J22,$G$2,,,) -> 231.12218
B23: Base Case | D23: =+D8/D13 -> 172.46693 | E23: =+D23*(1+E28) -> 181.09027 | F23: =+E23*(1+F28) -> 190.14479 | G23: =+F23*(1+G28) -> 199.65203 | H23: =+G23*(1+H28) -> 209.63463 | I23: =+H23*(1+I28) -> 220.11636 | J23: =+I23*(1+J28) -> 231.12218
B24: Bull Case | D24: =+D9/D14 -> 172.46693 | E24: =+D24*(1+E29) -> 182.81494 | F24: =+E24*(1+F29) -> 193.78384 | G24: =+F24*(1+G29) -> 205.41087 | H24: =+G24*(1+H29) -> 217.73552 | I24: =+H24*(1+I29) -> 230.79965 | J24: =+I24*(1+J29) -> 244.64763
B25: Bear Case | D25: =+D10/D15 -> 172.46693 | E25: =+D25*(1+E30) -> 175.91627 | F25: =+E25*(1+F30) -> 179.43459 | G25: =+F25*(1+G30) -> 183.02328 | H25: =+G25*(1+H30) -> 186.68375 | I25: =+H25*(1+I30) -> 190.41742 | J25: =+I25*(1+J30) -> 194.22577
B27: Average Price Growth United Estates & Canada | D27: =OFFSET(D27,$G$2,,,) | E27: =OFFSET(E27,$G$2,,,) -> 0.05 | F27: =OFFSET(F27,$G$2,,,) -> 0.05 | G27: =OFFSET(G27,$G$2,,,) -> 0.05 | H27: =OFFSET(H27,$G$2,,,) -> 0.05 | I27: =OFFSET(I27,$G$2,,,) -> 0.05 | J27: =OFFSET(J27,$G$2,,,) -> 0.05
B28: Base Case | E28: 0.05 | F28: 0.05 | G28: 0.05 | H28: 0.05 | I28: 0.05 | J28: 0.05
B29: Bull Case | E29: 0.06 | F29: 0.06 | G29: 0.06 | H29: 0.06 | I29: 0.06 | J29: 0.06
B30: Bear Case | E30: 0.02 | F30: 0.02 | G30: 0.02 | H30: 0.02 | I30: 0.02 | J30: 0.02
B32: Revenues EMEA | D32: =OFFSET(D32,$G$2,,,) -> 9699819 | E32: =OFFSET(E32,$G$2,,,) -> 10541278 | F32: =OFFSET(F32,$G$2,,,) -> 11455734 | G32: =OFFSET(G32,$G$2,,,) -> 12449519 | H32: =OFFSET(H32,$G$2,,,) -> 13529515 | I32: =OFFSET(I32,$G$2,,,) -> 14703200 | J32: =OFFSET(J32,$G$2,,,) -> 15978703
B33: Base Case | D33: 9699819 | E33: =+E38*E48 -> 10541278 | F33: =+F38*F48 -> 11455734 | G33: =+G38*G48 -> 12449519 | H33: =+H38*H48 -> 13529515 | I33: =+I38*I48 -> 14703200 | J33: =+J38*J48 -> 15978703
B34: Bull Case | D34: 9699819 | E34: =+E39*E49 -> 10795899 | F34: =+F39*F49 -> 12015835 | G34: =+G39*G49 -> 13373624 | H34: =+H39*H49 -> 14884844 | I34: =+I39*I49 -> 16566831 | J34: =+J39*J49 -> 18438883
B35: Bear Case | D35: 9699819 | E35: =+E40*E50 -> 10240099 | F35: =+F40*F50 -> 10810472 | G35: =+G40*G50 -> 11412616 | H35: =+H40*H50 -> 12048298 | I35: =+I40*I50 -> 12719389 | J35: =+J40*J50 -> 13427859
B37: Paid Mememberships EMEA | D37: =OFFSET(D37,$G$2,,,) -> 74036 | E37: =OFFSET(E37,$G$2,,,) -> 77737.8 | F37: =OFFSET(F37,$G$2,,,) -> 81624.69 | G37: =OFFSET(G37,$G$2,,,) -> 85705.924 | H37: =OFFSET(H37,$G$2,,,) -> 89991.221 | I37: =OFFSET(I37,$G$2,,,) -> 94490.782 | J37: =OFFSET(J37,$G$2,,,) -> 99215.321
B38: Base Case | D38: 74036 | E38: =+D38*(1+E43) -> 77737.8 | F38: =+E38*(1+F43) -> 81624.69 | G38: =+F38*(1+G43) -> 85705.924 | H38: =+G38*(1+H43) -> 89991.221 | I38: =+H38*(1+I43) -> 94490.782 | J38: =+I38*(1+J43) -> 99215.321
B39: Bull Case | D39: 74036 | E39: =+D39*(1+E44) -> 78478.16 | F39: =+E39*(1+F44) -> 83186.85 | G39: =+F39*(1+G44) -> 88178.061 | H39: =+G39*(1+H44) -> 93468.744 | I39: =+H39*(1+I44) -> 99076.869 | J39: =+I39*(1+J44) -> 105021.48
B40: Bear Case | D40: 74036 | E40: =+D40*(1+E45) -> 76627.26 | F40: =+E40*(1+F45) -> 79309.214 | G40: =+F40*(1+G45) -> 82085.037 | H40: =+G40*(1+H45) -> 84958.013 | I40: =+H40*(1+I45) -> 87931.543 | J40: =+I40*(1+J45) -> 91009.147
B42: Paid Mememberships Growth EMEA | D42: =OFFSET(D42,$G$2,,,) | E42: =OFFSET(E42,$G$2,,,) -> 0.05 | F42: =OFFSET(F42,$G$2,,,) -> 0.05 | G42: =OFFSET(G42,$G$2,,,) -> 0.05 | H42: =OFFSET(H42,$G$2,,,) -> 0.05 | I42: =OFFSET(I42,$G$2,,,) -> 0.05 | J42: =OFFSET(J42,$G$2,,,) -> 0.05
B43: Base Case | E43: 0.05 | F43: 0.05 | G43: 0.05 | H43: 0.05 | I43: 0.05 | J43: 0.05
B44: Bull Case | E44: 0.06 | F44: 0.06 | G44: 0.06 | H44: 0.06 | I44: 0.06 | J44: 0.06
B45: Bear Case | E45: 0.035 | F45: 0.035 | G45: 0.035 | H45: 0.035 | I45: 0.035 | J45: 0.035
B47: Average Price EMEA | D47: =OFFSET(D47,$G$2,,,) -> 131.0149 | E47: =OFFSET(E47,$G$2,,,) -> 135.60042 | F47: =OFFSET(F47,$G$2,,,) -> 140.34643 | G47: =OFFSET(G47,$G$2,,,) -> 145.25856 | H47: =OFFSET(H47,$G$2,,,) -> 150.34261 | I47: =OFFSET(I47,$G$2,,,) -> 155.6046 | J47: =OFFSET(J47,$G$2,,,) -> 161.05076
B48: Base Case | D48: 131.0149 | E48: =+D48*(1+E53) -> 135.60042 | F48: =+E48*(1+F53) -> 140.34643 | G48: =+F48*(1+G53) -> 145.25856 | H48: =+G48*(1+H53) -> 150.34261 | I48: =+H48*(1+I53) -> 155.6046 | J48: =+I48*(1+J53) -> 161.05076
B49: Bull Case | D49: 131.0149 | E49: =+D49*(1+E54) -> 137.56564 | F49: =+E49*(1+F54) -> 144.44393 | G49: =+F49*(1+G54) -> 151.66612 | H49: =+G49*(1+H54) -> 159.24943 | I49: =+H49*(1+I54) -> 167.2119 | J49: =+I49*(1+J54) -> 175.57249
B50: Bear Case | D50: 131.0149 | E50: =+D50*(1+E55) -> 133.6352 | F50: =+E50*(1+F55) -> 136.3079 | G50: =+F50*(1+G55) -> 139.03406 | H50: =+G50*(1+H55) -> 141.81474 | I50: =+H50*(1+I55) -> 144.65103 | J50: =+I50*(1+J55) -> 147.54405
B52: Average Price Growth EMEA | D52: =OFFSET(D52,$G$2,,,) | E52: =OFFSET(E52,$G$2,,,) -> 0.035 | F52: =OFFSET(F52,$G$2,,,) -> 0.035 | G52: =OFFSET(G52,$G$2,,,) -> 0.035 | H52: =OFFSET(H52,$G$2,,,) -> 0.035 | I52: =OFFSET(I52,$G$2,,,) -> 0.035 | J52: =OFFSET(J52,$G$2,,,) -> 0.035
...

Sheet Financial Statements
C2: Netflix
C3: Financial Statements
C5: Netflix - in $ thousands | D5: Q1-2022 | E5: Q2-2022 | F5: H1 2022 | G5: Run-rate | H5: Q3-2022 | I5: Q4-2022 | J5: 2022 | K5: Q1-2023 | L5: Q2-2023 | M5: Q3-2023 | N5: Q4-2023 | O5: 2023 | P5: 2024 | Q5: 2025
C6: Revenues | D6: 7867767 | E6: 7970141 | F6: =+E6+D6 -> 15837908 | G6: =+F6*2 -> 31675816
C7: COGS | D7: -4284705 | E7: -4690755 | F7: =+E7+D7 -> -8975460 | G7: =+F7*2 -> -17950920
C8: Gross Profit | D8: =+D7+D6 -> 3583062 | E8: =+E7+E6 -> 3279386 | F8: =+F7+F6 -> 6862448 | G8: =+G7+G6 -> 13724896
C9: Gross Margin | D9: =+D8/D$6 -> 0.45541028 | E9: =+E8/E$6 -> 0.41145897 | F9: =+F8/F$6 -> 0.43329258 | G9: =+G8/G$6 -> 0.43329258
C11: Adjusted COGS | G11: -4779280
C12: Adjusted Gross Profit | G12: =+G11+G73+G74 -> 8392360
C13: Adjusted Gross Margin | G13: 0.84911896
C15: Marketing | D15: -555978 | E15: -574960 | F15: =+E15+D15 -> -1130938 | G15: =+F15*2 -> -2261876
G16: =-G15/G$6 -> 0.071407032
C17: Technology and development | D17: -657530 | E17: -716846 | F17: =+E17+D17 -> -1374376 | G17: =+F17*2 -> -2748752
G18: =-G17/G$6 -> 0.086777622
C19: G&A | D19: -397928 | E19: -409297 | F19: =+E19+D19 -> -807225 | G19: =+F19*2 -> -1614450
G20: =-G19/G$6 -> 0.050967906
C21: EBIT | D21: =+D8+D15+D17+D19 -> 1971626 | E21: =+E8+E15+E17+E19 -> 1578283 | F21: =+F8+F15+F17+F19 -> 3549909 | G21: =+G8+G15+G17+G19 -> 7099818
C22: EBIT Margin | D22: =+D21/D$6 -> 0.25059537 | E22: =+E21/E$6 -> 0.19802448 | F22: =+F21/F$6 -> 0.22414002 | G22: =+G21/G$6 -> 0.22414002
C24: Interest expense | D24: -187579 | E24: -175455 | F24: =+E24+D24 -> -363034 | G24: =+F24*2 -> -726068
C25: Interest and other income | D25: 195645 | E25: 220226 | F25: =+E25+D25 -> 415871 | G25: =+F25*2 -> 831742
C26: Taxes | D26: -382245 | E26: -182103 | F26: =+E26+D26 -> -564348 | G26: =+F26*2 -> -1128696
C27: Net Income | D27: =+D21+D24+D25+D26 -> 1597447 | E27: =+E21+E24+E25+E26 -> 1440951 | F27: =+F21+F24+F25+F26 -> 3038398 | G27: =+G21+G24+G25+G26 -> 6076796
C28: EPS | D28: =+D27/D30 -> 3.5264976 | E28: =+E27/E30 -> 3.2009112 | F28: =+F27/F30 -> 6.7494608 | G28: =+G27/G30 -> 13.498922
C30: Diluted Shares | D30: 452984 | E30: 450169 | F30: =+E30 -> 450169 | G30: =+F30 -> 450169
C32: EBITDA | D32: =+D21+D73+D74 -> 5212593 | E32: =+E21+E73+E74 -> 4923136 | F32: =+F21+F73+F74 -> 10135729 | G32: =+G21+G73+G74 -> 20271458
C33: EBITDA Margin | D33: =+D32/D$6 -> 0.66252508 | E33: =+E32/E$6 -> 0.61769748 | F33: =+F32/F$6 -> 0.6399664 | G33: =+G32/G$6 -> 0.6399664
C36: Balance Sheet | D36: Q1-2022 | E36: Q2-2022
C37: Cash | D37: 6008946 | E37: 5819449
C38: Other current assets | D38: 2089069 | E38: 2021329
C39: Current Assets | D39: =+D37+D38 -> 8098015 | E39: =+E37+E38 -> 7840778
C41: Content assets | D41: 31191920 | E41: 32533199
C42: PP&E | D42: 1383763 | E42: 1361920
C43: Other non-current assets | D43: 4657206 | E43: 4615038
C44: Non-current Assets | D44: =+D41+D42+D43 -> 37232889 | E44: =+E41+E42+E43 -> 38510157
C46: Total Assets | D46: =+D39+D44 -> 45330904 | E46: =+E39+E44 -> 46350935
C48: Current content liabilities | D48: 4066289 | E48: 4174966
C49: Accounts payable | D49: 617202 | E49: 504278
C50: Accrued expenses and other liabilities | D50: 1817117 | E50: 1596035
C51: Deferred revenue | D51: 1239048 | E51: 1224743
C52: Short-term debt | D52: 0 | E52: 0
...

Sheet Model
C2: Netflix | E2: SCENARIO SELECTION -> | H2: 1
C3: Model | H3: =IF(H2=1,"Base Case", IF(H2=2,"Bull Case", IF(H2=3,"Bear Case","-"))) -> Base Case
C5: Netflix | E5: SCENARIO SELECTION -> | H5: =+Valuation!M2 -> 1
C6: Financial Model | H6: =IF(H5=1,"Base Case", IF(H5=2,"Bull Case", IF(H5=3,"Bear Case","-"))) -> Base Case
C8: Netflix - in $ thousands | D8: 2017 | E8: =+D8+1 -> 2018 | F8: =+E8+1 -> 2019 | G8: =+F8+1 -> 2020 | H8: =+G8+1 -> 2021 | I8: =+H8+1 -> 2022 | J8: =+I8+1 -> 2023 | K8: =+J8+1 -> 2024 | L8: =+K8+1 -> 2025 | M8: =+L8+1 -> 2026 | N8: Afterwards
C9: Revenues United Estates & Canada | D9: 6660859 | E9: 8281532 | F9: 10051208 | G9: 11455396 | H9: 12972100 | I9: =+Assumptions!E7 -> 13893119 | J9: =+Assumptions!F7 -> 14879531 | K9: =+Assumptions!G7 -> 15935977 | L9: =+Assumptions!H7 -> 17067432 | M9: =+Assumptions!I7 -> 18279219
C10: Paid net membership additions | D10: 5512 | E10: 6335 | F10: 2905 | G10: 6274 | H10: 1279 | I10: =+I11-H11 -> 1504.3 | J10: =+J11-I11 -> 1534.386 | K10: =+K11-J11 -> 1565.0737 | L10: =+L11-K11 -> 1596.3752 | M10: =+M11-L11 -> 1628.3027
C11: Paid memberships at end of period | D11: 58422 | E11: 64757 | F11: 67662 | G11: 73936 | H11: 75215 | I11: =+Assumptions!E12 -> 76719.3 | J11: =+Assumptions!F12 -> 78253.686 | K11: =+Assumptions!G12 -> 79818.76 | L11: =+Assumptions!H12 -> 81415.135 | M11: =+Assumptions!I12 -> 83043.438
C12: Average price | D12: =+D9/D11 -> 114.01285 | E12: =+E9/E11 -> 127.88628 | F12: =+F9/F11 -> 148.55026 | G12: =+G9/G11 -> 154.93665 | H12: =+H9/H11 -> 172.46693 | I12: =+Assumptions!E22 -> 181.09027 | J12: =+Assumptions!F22 -> 190.14479 | K12: =+Assumptions!G22 -> 199.65203 | L12: =+Assumptions!H22 -> 209.63463 | M12: =+Assumptions!I22 -> 220.11636
C13: Average price growth as % | E13: =+E12/D12-1 -> 0.12168301 | F13: =+F12/E12-1 -> 0.16158091 | G13: =+G12/F12-1 -> 0.042991397 | H13: =+H12/G12-1 -> 0.11314483 | I13: =+I12/H12-1 -> 0.05 | J13: =+J12/I12-1 -> 0.05 | K13: =+K12/J12-1 -> 0.05 | L13: =+L12/K12-1 -> 0.05 | M13: =+M12/L12-1 -> 0.05
C14: Membership growth as % | E14: =+E11/D11-1 -> 0.10843518 | F14: =+F11/E11-1 -> 0.044860015 | G14: =+G11/F11-1 -> 0.092725607 | H14: =+H11/G11-1 -> 0.017298745 | I14: =+I11/H11-1 -> 0.02 | J14: =+J11/I11-1 -> 0.02 | K14: =+K11/J11-1 -> 0.02 | L14: =+L11/K11-1 -> 0.02 | M14: =+M11/L11-1 -> 0.02
C16: Revenues EMEA | D16: 2362813 | E16: 3963707 | F16: 5543067 | G16: 7772252 | H16: 9699819 | I16: =+Assumptions!E32 -> 10541278 | J16: =+Assumptions!F32 -> 11455734 | K16: =+Assumptions!G32 -> 12449519 | L16: =+Assumptions!H32 -> 13529515 | M16: =+Assumptions!I32 -> 14703200
C17: Paid net membership additions | D17: 8173 | E17: 11814 | F17: 13960 | G17: 14920 | H17: 7338 | I17: =+I18-H18 -> 3701.8 | J17: =+J18-I18 -> 3886.89 | K17: =+K18-J18 -> 4081.2345 | L17: =+L18-K18 -> 4285.2962 | M17: =+M18-L18 -> 4499.561
C18: Paid memberships at end of period | D18: 26004 | E18: 37818 | F18: 51778 | G18: 66698 | H18: 74036 | I18: =+Assumptions!E37 -> 77737.8 | J18: =+Assumptions!F37 -> 81624.69 | K18: =+Assumptions!G37 -> 85705.924 | L18: =+Assumptions!H37 -> 89991.221 | M18: =+Assumptions!I37 -> 94490.782
C19: Average price | D19: =+D16/D18 -> 90.863444 | E19: =+E16/E18 -> 104.81006 | F19: =+F16/F18 -> 107.05448 | G19: =+G16/G18 -> 116.52901 | H19: =+H16/H18 -> 131.0149 | I19: =+Assumptions!E47 -> 135.60042 | J19: =+Assumptions!F47 -> 140.34643 | K19: =+Assumptions!G47 -> 145.25856 | L19: =+Assumptions!H47 -> 150.34261 | M19: =+Assumptions!I47 -> 155.6046
C20: Average price growth as % | E20: =+E19/D19-1 -> 0.15348989 | F20: =+F19/E19-1 -> 0.021414152 | G20: =+G19/F19-1 -> 0.088501934 | H20: =+H19/G19-1 -> 0.12431142 | I20: =+I19/H19-1 -> 0.035 | J20: =+J19/I19-1 -> 0.035 | K20: =+K19/J19-1 -> 0.035 | L20: =+L19/K19-1 -> 0.035 | M20: =+M19/L19-1 -> 0.035
C21: Membership growth as % | E21: =+E18/D18-1 -> 0.45431472 | F21: =+F18/E18-1 -> 0.36913639 | G21: =+G18/F18-1 -> 0.28815327 | H21: =+H18/G18-1 -> 0.11001829 | I21: =+I18/H18-1 -> 0.05 | J21: =+J18/I18-1 -> 0.05 | K21: =+K18/J18-1 -> 0.05 | L21: =+L18/K18-1 -> 0.05 | M21: =+M18/L18-1 -> 0.05
C23: Revenues LATAM | D23: 1642616 | E23: 2237697 | F23: 2795434 | G23: 3156727 | H23: 3576976 | I23: =+Assumptions!E57 -> 3887278.7 | J23: =+Assumptions!F57 -> 4224500.1 | K23: =+Assumptions!G57 -> 4590975.5 | L23: =+Assumptions!H57 -> 4989242.6 | M23: =+Assumptions!I57 -> 5422059.4
C24: Paid net membership additions | D24: 5509 | E24: 6360 | F24: 5340 | G24: 6120 | H24: 2424 | I24: =+I25-H25 -> 1998.05 | J24: =+J25-I25 -> 2097.9525 | K24: =+K25-J25 -> 2202.8501 | L24: =+L25-K25 -> 2312.9926 | M24: =+M25-L25 -> 2428.6423
C25: Paid memberships at end of period | D25: 19717 | E25: 26077 | F25: 31417 | G25: 37537 | H25: 39961 | I25: =+Assumptions!E62 -> 41959.05 | J25: =+Assumptions!F62 -> 44057.003 | K25: =+Assumptions!G62 -> 46259.853 | L25: =+Assumptions!H62 -> 48572.845 | M25: =+Assumptions!I62 -> 51001.488
C26: Average price | D26: =+D23/D25 -> 83.309631 | E26: =+E23/E25 -> 85.811136 | F26: =+F23/F25 -> 88.978387 | G26: =+G23/G25 -> 84.096412 | H26: =+H23/H25 -> 89.511674 | I26: =+Assumptions!E72 -> 92.644582 | J26: =+Assumptions!F72 -> 95.887143 | K26: =+Assumptions!G72 -> 99.243193 | L26: =+Assumptions!H72 -> 102.7167 | M26: =+Assumptions!I72 -> 106.31179
C27: Average price growth as % | E27: =+E26/D26-1 -> 0.0300266 | F27: =+F26/E26-1 -> 0.03690956 | G27: =+G26/F26-1 -> -0.054866986 | H27: =+H26/G26-1 -> 0.064393501 | I27: =+I26/H26-1 -> 0.035 | J27: =+J26/I26-1 -> 0.035 | K27: =+K26/J26-1 -> 0.035 | L27: =+L26/K26-1 -> 0.035 | M27: =+M26/L26-1 -> 0.035
C28: Membership growth as % | E28: =+E25/D25-1 -> 0.32256428 | F28: =+F25/E25-1 -> 0.20477816 | G28: =+G25/F25-1 -> 0.19479899 | H28: =+H25/G25-1 -> 0.064576285 | I28: =+I25/H25-1 -> 0.05 | J28: =+J25/I25-1 -> 0.05 | K28: =+K25/J25-1 -> 0.05 | L28: =+L25/K25-1 -> 0.05 | M28: =+M25/L25-1 -> 0.05
C30: Revenues Asia-Pacific | D30: 575928 | E30: 945816 | F30: 1469521 | G30: 2372300 | H30: 3266601 | I30: =+Assumptions!E82 -> 3944420.7 | J30: =+Assumptions!F82 -> 4717527.2 | K30: =+Assumptions!G82 -> 5223482 | L30: =+Assumptions!H82 -> 5649195.7 | M30: =+Assumptions!I82 -> 5964138.4
C31: Paid net membership additions | D31: 2360 | E31: 4106 | F31: 5636 | G31: 9259 | H31: 7140 | I31: =+I32-H31 -> 30386.8 | J31: =+J32-I31 -> 12769.02 | K31: =+K32-J31 -> 33623.486 | L31: =+L32-K31 -> 15088.645 | M31: =+M32-L31 -> 34841.29
C32: Paid memberships at end of period | D32: 6501 | E32: 10607 | F32: 16233 | G32: 25492 | H32: 32632 | I32: =+Assumptions!E87 -> 37526.8 | J32: =+Assumptions!F87 -> 43155.82 | K32: =+Assumptions!G87 -> 46392.507 | L32: =+Assumptions!H87 -> 48712.132 | M32: =+Assumptions!I87 -> 49929.935
C33: Average price | D33: =+D30/D32 -> 88.590678 | E33: =+E30/E32 -> 89.169039 | F33: =+F30/F32 -> 90.526766 | G33: =+G30/G32 -> 93.060568 | H33: =+H30/H32 -> 100.10422 | I33: =+Assumptions!E97 -> 105.10943 | J33: =+Assumptions!F97 -> 109.31381 | K33: =+Assumptions!G97 -> 112.59323 | L33: =+Assumptions!H97 -> 115.97102 | M33: =+Assumptions!I97 -> 119.45015
C34: Average price growth as % | E34: =+E33/D33-1 -> 0.0065284629 | F34: =+F33/E33-1 -> 0.015226441 | G34: =+G33/F33-1 -> 0.027989529 | H34: =+H33/G33-1 -> 0.07568893 | I34: =+I33/H33-1 -> 0.05 | J34: =+J33/I33-1 -> 0.04 | K34: =+K33/J33-1 -> 0.03 | L34: =+L33/K33-1 -> 0.03 | M34: =+M33/L33-1 -> 0.03
C35: Membership growth as % | E35: =+E32/D32-1 -> 0.63159514 | F35: =+F32/E32-1 -> 0.53040445 | G35: =+G32/F32-1 -> 0.57038132 | H35: =+H32/G32-1 -> 0.28008787 | I35: =+I32/H32-1 -> 0.15 | J35: =+J32/I32-1 -> 0.15 | K35: =+K32/J32-1 -> 0.075 | L35: =+L32/K32-1 -> 0.05 | M35: =+M32/L32-1 -> 0.025
C37: Total Memberships Revenues | D37: =+D30+D23+D16+D9 -> 11242216 | E37: =+E30+E23+E16+E9 -> 15428752 | F37: =+F30+F23+F16+F9 -> 19859230 | G37: =+G30+G23+G16+G9 -> 24756675 | H37: =+H30+H23+H16+H9 -> 29515496 | I37: =+I30+I23+I16+I9 -> 32266097 | J37: =+J30+J23+J16+J9 -> 35277292 | K37: =+K30+K23+K16+K9 -> 38199954 | ... M37: =+M30+M23+M16+M9 -> 44368617
C38: Other Revenues | D38: =+D40-D37 -> 450497 | E38: =+E40-E37 -> 365589 | F38: =+F40-F37 -> 297217 | G38: =+G40-G37 -> 239381 | H38: =+H40-H37 -> 182348 | I38: =+Assumptions!E107 -> 136761 | J38: =+Assumptions!F107 -> 95732.7 | K38: =+Assumptions!G107 -> 62226.255 | L38: =+Assumptions!H107 -> 31113.127 | M38: =+Assumptions!I107 -> 0
C39: Other Revenues Growth as % | E39: =+E38/D38-1 -> -0.18847628 | F39: =+F38/E38-1 -> -0.18701876 | G39: =+G38/F38-1 -> -0.19459183 | H39: =+H38/G38-1 -> -0.23825199 | I39: =+I38/H38-1 -> -0.25 | J39: =+J38/I38-1 -> -0.3 | K39: =+K38/J38-1 -> -0.35 | L39: =+L38/K38-1 -> -0.5 | M39: =+M38/L38-1 -> -1
C40: Total Revenues | D40: 11692713 | E40: 15794341 | F40: 20156447 | G40: 24996056 | H40: 29697844 | I40: =+I38+I37 -> 32402858 | J40: =+J38+J37 -> 35373025 | K40: =+K38+K37 -> 38262180 | L40: =+L38+L37 -> 41266498 | M40: =+M38+M37 -> 44368617
C41: Total Revenue Growth | E41: =+E40/D40-1 -> 0.35078497 | F41: =+F40/E40-1 -> 0.27618158 | G41: =+G40/F40-1 -> 0.24010229 | H41: =+H40/G40-1 -> 0.18810119 | I41: =+I40/H40-1 -> 0.091084517 | J41: =+J40/I40-1 -> 0.091663734 | K41: =+K40/J40-1 -> 0.081676796 | L41: =+L40/K40-1 -> 0.078519257 | M41: =+M40/L40-1 -> 0.075172829
C43: COGS | D43: -8033000 | E43: -9967538 | F43: -12440213 | G43: -15276319 | H43: -17332683
C44: D&A of Content | D44: =+D104 -> 6197817 | E44: =+E104 -> 7532088 | F44: =+F104 -> 9216247 | G44: =+G104 -> 10806912 | H44: =+H104 -> 12230367
C45: D&A of PPE | D45: =+D105 -> 71911 | E45: =+E105 -> 83157 | F45: =+F105 -> 103579 | G45: =+G105 -> 115710 | H45: =+H105 -> 208412
C46: Adjusted COGS | D46: =+D44+D43+D45 -> -1763272 | E46: =+E44+E43+E45 -> -2352293 | F46: =+F44+F43+F45 -> -3120387 | G46: =+G44+G43+G45 -> -4353697 | H46: =+H44+H43+H45 -> -4893904 | I46: =-I40*Assumptions!E117 -> -4892831.5 | J46: =-J40*Assumptions!F117 -> -5341326.7 | K46: =-K40*Assumptions!G117 -> -5777589.2 | L46: =-L40*Assumptions!H117 -> -6231241.2 | M46: =-M40*Assumptions!I117 -> -6699661.2
C47: Gross Profit | D47: =+D40+D46 -> 9929441 | E47: =+E40+E46 -> 13442048 | F47: =+F40+F46 -> 17036060 | G47: =+G40+G46 -> 20642359 | H47: =+H40+H46 -> 24803940 | I47: =+I40+I46 -> 27510026 | J47: =+J40+J46 -> 30031698 | K47: =+K40+K46 -> 32484591 | ... M47: =+M40+M46 -> 37668956
C48: Gross Margin | D48: =IFERROR(+D47/D$40,"-") -> 0.84919907 | E48: =IFERROR(+E47/E$40,"-") -> 0.85106735 | F48: =IFERROR(+F47/F$40,"-") -> 0.84519162 | G48: =IFERROR(+G47/G$40,"-") -> 0.82582464 | H48: =IFERROR(+H47/H$40,"-") -> 0.83521013 | I48: =IFERROR(+I47/I$40,"-") -> 0.849 | J48: =IFERROR(+J47/J$40,"-") -> 0.849 | K48: =IFERROR(+K47/K$40,"-") -> 0.849 | ... M48: =IFERROR(+M47/M$40,"-") -> 0.849
...

Sheet Valuation
C2: Netflix | I2: SCENARIO SELECTION -> | M2: 1
C3: Valuation | M3: =IF(M2=1,"Base Case", IF(M2=2,"Bull Case", IF(M2=3,"Bear Case","-"))) -> Base Case
H4: 1 | I4: 1 | J4: =+I4+1 -> 2 | K4: =+J4+1 -> 3 | L4: =+K4+1 -> 4 | M4: =+L4+1 -> 5
C5: VALUATION | I5: 2022E | J5: 2023E | K5: 2024E | L5: 2025E | M5: 2026E | O5: Current Valuation Metrics (USD m) | P5: 2022E | R5: Valuation Metrics (USD m) | S5: FY 2021A | T5: FY 2022E | U5: FY 2023E | V5: FY 2024E
C6: EBITDA | I6: =+Model!I218 -> 20705426 | J6: =+Model!J218 -> 22691795 | K6: =+Model!K218 -> 24736499 | L6: =+Model!L218 -> 26678791 | M6: =+Model!M218 -> 28795233 | O6: #VALUE! | P6: {=_FV(O6,"Precio")} -> #NAME? | R6: Current Price | S6: =+$P$6 -> #NAME? | T6: =+$P$6 -> #NAME? | U6: =+$P$6 -> #NAME? | V6: =+$P$6 -> #NAME?
C7: Taxes | I7: =+Model!I219 -> -1865860.3 | J7: =+Model!J219 -> -1183554.5 | K7: =+Model!K219 -> -488002.07 | L7: =+Model!L219 -> 253288.98 | M7: =+Model!M219 -> -2074997.9
C8: Change in Working Capital | I8: =+Model!I222 -> 3586472.5 | J8: =+Model!J222 -> 410106.93 | K8: =+Model!K222 -> 413213.97 | L8: =+Model!L222 -> 425520.21 | M8: =+Model!M222 -> 437202.62 | O8: Shares outstading | P8: =+$M$24 -> 455372 | R8: Shares outstading | S8: =+$M$24 -> 455372 | T8: =+$M$24 -> 455372 | U8: =+$M$24 -> 455372 | V8: =+$M$24 -> 455372
C9: Other Balance Sheet Changes | I9: =+Model!I220+Model!I221 -> 127733.4 | J9: =+Model!J220+Model!J221 -> -154448.68 | K9: =+Model!K220+Model!K221 -> -150236.08 | L9: =+Model!L220+Model!L221 -> -156224.53 | M9: =+Model!M220+Model!M221 -> -161310.21 | O9: Market Cap | P9: =+P8*P6 -> #NAME? | R9: Market Cap | S9: =+S8*S6 -> #NAME? | T9: =+T8*T6 -> #NAME? | U9: =+U8*U6 -> #NAME? | V9: =+V8*V6 -> #NAME?
C10: Operating Cash Flow | I10: =SUM(I6:I9) -> 22553772 | J10: =SUM(J6:J9) -> 21763899 | K10: =SUM(K6:K9) -> 24511475 | L10: =SUM(L6:L9) -> 27201376 | M10: =SUM(M6:M9) -> 26996127 | O10: (+) Financial Debt | P10: =+Model!H91+Model!$H$87 -> 15392895 | R10: (+) Financial Debt | S10: =+$P$10 -> 15392895 | T10: =+$P$10 -> 15392895 | U10: =+$P$10 -> 15392895 | V10: =+$P$10 -> 15392895
O11: (-)/(+) Working Capital | P11: =+(Model!H72+Model!H73-Model!H83-Model!H84-Model!H85-Model!H86-Model!H90) -> -8841335 | R11: (-)/(+) Working Capital | S11: =+$P$11 -> -8841335 | T11: =+$P$11 -> -8841335 | U11: =+$P$11 -> -8841335 | V11: =+$P$11 -> -8841335
C12: Maintenance CapEx | I12: =+Model!I231+Model!I232 -> -18565994 | J12: =+Model!J231+Model!J232 -> -19058225 | K12: =+Model!K231+Model!K232 -> -19560744 | L12: =+Model!L231+Model!L232 -> -20076383 | M12: =+Model!M231+Model!M232 -> -20605209 | O12: (+) Other | P12: 0 | R12: (+) Other | S12: =+$P$12 -> 0 | T12: =+$P$12 -> 0 | U12: =+$P$12 -> 0 | V12: =+$P$12 -> 0
C13: Growth CapEx | O13: (-) Cash | P13: =-Model!H71 -> -6027804 | R13: (-) Cash | S13: =+$P$13 -> -6027804 | T13: =+$P$13 -> -6027804 | U13: =+$P$13 -> -6027804 | V13: =+$P$13 -> -6027804
C14: Free Cash Flow | I14: =+I10+I12+I13 -> 3987777.6 | J14: =+J10+J12+J13 -> 2705673.8 | K14: =+K10+K12+K13 -> 4950731.5 | L14: =+L10+L12+L13 -> 7124992.4 | M14: =+M10+M12+M13 -> 6390918.5 | O14: EV | P14: =+SUM(P9:P13) -> #NAME? | R14: EV | S14: =+SUM(S9:S13) -> #NAME? | T14: =+SUM(T9:T13) -> #NAME? | U14: =+SUM(U9:U13) -> #NAME? | V14: =+SUM(V9:V13) -> #NAME?
C15: WACC | G15: 0.25
C16: Discount Factor | I16: =1/(1+$G$15)^I4 -> 0.8 | J16: =1/(1+$G$15)^J4 -> 0.64 | K16: =1/(1+$G$15)^K4 -> 0.512 | L16: =1/(1+$G$15)^L4 -> 0.4096 | M16: =1/(1+$G$15)^M4 -> 0.32768 | O16: EBIT LTM | P16: =+Model!I61 -> 8164605.4 | R16: EBIT LTM | S16: =+Model!H61 -> 6194509 | T16: =+Model!I61 -> 8164605.4 | U16: =+Model!J61 -> 5428965.4 | V16: =+Model!K61 -> 2629505.8
O17: EV/EBIT | P17: =+P14/P16 -> #NAME? | R17: EV/EBIT | S17: =+S14/S16 -> #NAME? | T17: =+T14/T16 -> #NAME? | U17: =+U14/U16 -> #NAME? | V17: =+V14/V16 -> #NAME?
C18: Terminal Value - on FCF | G18: 15 | M18: =+M14*G18 -> 95863777
C19: UFCF plus TV | I19: =+I18+I14 -> 3987777.6 | J19: =+J18+J14 -> 2705673.8 | K19: =+K18+K14 -> 4950731.5 | L19: =+L18+L14 -> 7124992.4 | M19: =+M18+M14 -> 1.022547e+08 | O19: Net Profit LTM | P19: =+Model!I67 -> 5597580.9 | R19: Operating Cash Flow LTM | T19: =+I10 -> 22553772 | U19: =+J10 -> 21763899 | V19: =+K10 -> 24511475
C20: PV of UFCF plus TV | I20: =I19*I16 -> 3190222 | J20: =J19*J16 -> 1731631.2 | K20: =K19*K16 -> 2534774.5 | L20: =L19*L16 -> 2918396.9 | M20: =M19*M16 -> 33506819 | O20: PE | P20: =+P9/P19 -> #NAME? | R20: EV/OCF LTM | T20: =+T14/T19 -> #NAME? | U20: =+U14/U19 -> #NAME? | V20: =+V14/V19 -> #NAME?
C21: Enterprise Value | M21: =+SUM(I20:M20) -> 43881843 | O21: PE Ex-Cash | R21: EqV/OCF LTM | T21: =+T9/T19 -> #NAME? | U21: =+U9/U19 -> #NAME? | V21: =+V9/V19 -> #NAME?
C22: Less Current Net Debt at 31/12/2021 | M22: =-(Model!H87+Model!H91-Model!H71) -> -9365091
C23: Equity Value | M23: =+M22+M21 -> 34516752 | O23: EBITDA LTM | P23: =+Model!I56 -> 20705426 | R23: Normalized FCF | T23: =+I14-I13 -> 3987777.6 | U23: =+J14-J13 -> 2705673.8 | V23: =+K14-K13 -> 4950731.5
C24: Shares Outstanding | M24: 455372 | O24: EV/EBITDA LTM | P24: =+P14/P23 -> #NAME? | R24: Normalized FCF Yield | T24: =+T23/T9 -> #NAME? | U24: =+U23/U9 -> #NAME? | V24: =+V23/V9 -> #NAME?
C25: Equity Value per Share in USD | M25: =IFERROR(+M23/M24,0) -> 75.799022
C27: WACC and TV Multiple Impact on Equity Value per Share
I28: Exit TV Multiple
E29: =+M25 -> 75.799022 | F29: =+G29-1 -> 12 | G29: =+H29-1 -> 13 | H29: =+I29-1 -> 14 | I29: 15 | J29: =+I29+1 -> 16 | K29: =+J29+1 -> 17 | L29: =+K29+1 -> 18
E30: =E31-0.025 -> 0.2 | F30: 78.017141 | G30: 83.657292 | H30: 89.297443 | I30: 94.937594 | J30: 100.57775 | K30: 106.2179 | L30: 111.85805
D31: WACC | E31: =E32-0.025 -> 0.225 | F31: 69.544136 | G31: 74.631778 | H31: 79.719419 | I31: 84.807061 | J31: 89.894703 | K31: 94.982344 | L31: 100.06999
D32: Value | E32: 0.25 | F32: 62.002547 | G32: 66.601372 | H32: 71.200197 | I32: 75.799022 | J32: 80.397847 | K32: 84.996672 | L32: 89.595497
E33: =+E32+2.5% -> 0.275 | F33: 55.272542 | G33: 59.43784 | H33: 63.603138 | I33: 67.768435 | J33: 71.933733 | K33: 76.09903 | L33: 80.264328
E34: =+E33+2.5% -> 0.3 | F34: 49.251746 | G34: 53.031644 | H34: 56.811543 | I34: 60.591442 | J34: 64.371341 | K34: 68.15124 | L34: 71.931139
